Workbook

Sheet Executive Summary
A1: KICC — 87-Pipeline Revenue Model: Executive Summary
A2: Phased-launch, ramp-adjusted projection across all 87 catalog pipelines, net of advertising & media cost. Figures are modeled estimates — see Assumptions tab.
A4: Year | B4: Year 1 | C4: Year 2 | D4: Year 3 | E4: Year 4 | F4: Year 5
A5: Gross revenue (KSh/yr) | B5: ='Pipeline Model'!F90 | C5: ='Pipeline Model'!G90 | D5: ='Pipeline Model'!H90 | E5: ='Pipeline Model'!I90 | F5: ='Pipeline Model'!J90
A6: Less: advertising & media cost (KSh/yr) | B6: =-'Advertising & Media Cost'!D18 | C6: =-'Advertising & Media Cost'!G18 | D6: =-'Advertising & Media Cost'!J18 | E6: =-'Advertising & Media Cost'!M18 | F6: =-'Advertising & Media Cost'!P18
A7: of which: Screentime (TV/digital/OOH) | B7: ='Advertising & Media Cost'!E18 | C7: ='Advertising & Media Cost'!H18 | D7: ='Advertising & Media Cost'!K18 | E7: ='Advertising & Media Cost'!N18 | F7: ='Advertising & Media Cost'!Q18
A8: of which: Airtime (radio/mobile) | B8: ='Advertising & Media Cost'!F18 | C8: ='Advertising & Media Cost'!I18 | D8: ='Advertising & Media Cost'!L18 | E8: ='Advertising & Media Cost'!O18 | F8: ='Advertising & Media Cost'!R18
A9: Net revenue after advertising (KSh/yr) | B9: =B5+B6 | C9: =C5+C6 | D9: =D5+D6 | E9: =E5+E6 | F9: =F5+F6
A10: Net revenue after advertising (USD/yr) | B10: =B9/Assumptions!$C$3 | C10: =C9/Assumptions!$C$3 | D10: =D9/Assumptions!$C$3 | E10: =E9/Assumptions!$C$3 | F10: =F9/Assumptions!$C$3
A11: Net run-rate at year-end (USD/month) | B11: =B10/12 | C11: =C10/12 | D11: =D10/12 | E11: =E10/12 | F11: =F10/12
A12: Target run-rate (USD/month) | B12: 12000000 | C12: 12000000 | D12: 12000000 | E12: 12000000 | F12: 12000000
A13: Gap to target (USD/month) | B13: =B11-B12 | C13: =C11-C12 | D13: =D11-D12 | E13: =E11-E12 | F13: =F11-F12
A15: Key takeaways
A16: - Revenue compounds as later-wave pipelines (minerals, energy, financial services, flagship/investment) come
A17: online and earlier waves (real estate, tourism, marketplace) mature past their ramp period.
A18: - Advertising & media cost (screentime + airtime) is modeled as a declining share of revenue — KSh 33.7 million
A19: in Year 1 rising to KSh 286.8 million in Year 5 — and is deducted before the net run-rate figures above.
A20: - Even net of advertising cost, the model lands short of a $12,000,000/month steady-state target by Year 5 —
A21: the honest ceiling given realistic adoption ramps, not a shortfall to be closed by adding more pipelines.
A22: - Minerals, Energy, and Flagship/Investment lines are back-loaded (Year 3-5 launch) and licence/regulation-
A23: gated in places (direct lending, equity), so they carry the most execution and regulatory risk in the model.

Sheet Assumptions
A1: KICC 87-Pipeline Revenue Model — Assumptions & Methodology
B3: FX rate (KSh per USD) | C3: 129 | D3: Input — update to current CBK reference rate
B4: Uniform scale factor applied to base pipeline-size estimates | C4: 1.5 | D4: Input — sensitivity lever; see note below
B6: Adoption ramp curve (share of steady-state maturity revenue reached, by years since a pipeline's launch)
B7: Years since launch | C7: Ramp %
B8: 1 | C8: 0.15 | D8: Launch year itself: still ramping up (onboarding, trust-building)
B9: 2 | C9: 0.45
B10: 3 | C10: 0.75
B11: 4 | C11: 0.95
B12: 5 | C12: 1 | D12: Year 5+ since launch: treated as fully mature for this model
B14: Advertising & media spend — % of that year's revenue (economy-wide)
B15: Year | C15: Marketing % of revenue
B16: Year 1 | C16: 0.14 | D16: Declining spend-to-revenue ratio as the platform matures (word-of-mouth/repeat usage substitute for paid reach) — absolute KSh spend still grows with revenue.
B17: Year 2 | C17: 0.11
B18: Year 3 | C18: 0.09
B19: Year 4 | C19: 0.07
B20: Year 5 | C20: 0.06
B22: Advertising channel split by category — Screentime (TV, digital display/OOH, cinema) vs. Airtime (radio, mobile airtime/SMS, USSD)
B23: Category | C23: Screentime % | D23: Airtime %
B24: A. Agriculture | C24: 0.3 | D24: 0.7 | E24: Rural/smallholder-heavy categories skew to radio airtime; urban/digital-native categories skew to screentime.
B25: B. Minerals | C25: 0.4 | D25: 0.6
B26: C. Industrial & SEZ | C26: 0.6 | D26: 0.4
B27: D. Energy & Infra | C27: 0.55 | D27: 0.45
B28: E. Real Estate | C28: 0.7 | D28: 0.3
B29: F. Tourism | C29: 0.75 | D29: 0.25
B30: G. Commerce & Discovery | C30: 0.65 | D30: 0.35
B31: H. Logistics | C31: 0.5 | D31: 0.5
B32: I. Financial Services | C32: 0.6 | D32: 0.4
B33: J. Government | C33: 0.35 | D33: 0.65
B34: K. Additional Sectors | C34: 0.5 | D34: 0.5
B35: L. RE Rental Expansion | C35: 0.7 | D35: 0.3
B36: M. Flagship & Investment | C36: 0.65 | D36: 0.35
B38: Methodology notes
B39: 1. Each of the 87 pipelines in the catalog is assigned a category, a Launch Year (1-5), and a Steady-State
B40: Annual Revenue estimate at full maturity (KSh), on the 'Pipeline Model' sheet.
B41: 2. Steady-state values are MODELED ESTIMATES, not sourced third-party market sizing. They were derived from
B42: the qualitative scale signals in the pipeline catalog itself (e.g. 'largest single export earner' vs.
B43: 'early-stage/exploration', stated commission ranges). Replace with sourced sector data (KNBS, CBK, sector
B44: board reports) before this model is used for fundraising or budget commitments.
B45: 3. Revenue in any given year = Steady-State Value x Scale Factor x Ramp% for (current year - launch year).
...

Sheet Pipeline Model
A1: ID | B1: Pipeline | C1: Category | D1: Launch Year | E1: Steady-State Revenue at Maturity (KSh/yr) | F1: Year 1 (KSh) | G1: Year 2 (KSh) | H1: Year 3 (KSh) | I1: Year 4 (KSh) | J1: Year 5 (KSh)
A2: 1 | B2: Coffee aggregation & export match | C2: A. Agriculture | D2: 2 | E2: 120000000 | F2: =IF(1<$D2,0,$E2*Assumptions!$C$4*INDEX(Assumptions!$C$8:$C$12,MIN(1-$D2+1,5))) | G2: =IF(2<$D2,0,$E2*Assumptions!$C$4*INDEX(Assumptions!$C$8:$C$12,MIN(2-$D2+1,5))) | H2: =IF(3<$D2,0,$E2*Assumptions!$C$4*INDEX(Assumptions!$C$8:$C$12,MIN(3-$D2+1,5))) | I2: =IF(4<$D2,0,$E2*Assumptions!$C$4*INDEX(Assumptions!$C$8:$C$12,MIN(4-$D2+1,5))) | J2: =IF(5<$D2,0,$E2*Assumptions!$C$4*INDEX(Assumptions!$C$8:$C$12,MIN(5-$D2+1,5)))
A3: 2 | B3: Tea (non-KTDA / specialty) | C3: A. Agriculture | D3: 3 | E3: 60000000 | F3: =IF(1<$D3,0,$E3*Assumptions!$C$4*INDEX(Assumptions!$C$8:$C$12,MIN(1-$D3+1,5))) | G3: =IF(2<$D3,0,$E3*Assumptions!$C$4*INDEX(Assumptions!$C$8:$C$12,MIN(2-$D3+1,5))) | H3: =IF(3<$D3,0,$E3*Assumptions!$C$4*INDEX(Assumptions!$C$8:$C$12,MIN(3-$D3+1,5))) | I3: =IF(4<$D3,0,$E3*Assumptions!$C$4*INDEX(Assumptions!$C$8:$C$12,MIN(4-$D3+1,5))) | J3: =IF(5<$D3,0,$E3*Assumptions!$C$4*INDEX(Assumptions!$C$8:$C$12,MIN(5-$D3+1,5)))
A4: 3 | B4: Maize domestic distribution | C4: A. Agriculture | D4: 2 | E4: 90000000 | F4: =IF(1<$D4,0,$E4*Assumptions!$C$4*INDEX(Assumptions!$C$8:$C$12,MIN(1-$D4+1,5))) | G4: =IF(2<$D4,0,$E4*Assumptions!$C$4*INDEX(Assumptions!$C$8:$C$12,MIN(2-$D4+1,5))) | H4: =IF(3<$D4,0,$E4*Assumptions!$C$4*INDEX(Assumptions!$C$8:$C$12,MIN(3-$D4+1,5))) | I4: =IF(4<$D4,0,$E4*Assumptions!$C$4*INDEX(Assumptions!$C$8:$C$12,MIN(4-$D4+1,5))) | J4: =IF(5<$D4,0,$E4*Assumptions!$C$4*INDEX(Assumptions!$C$8:$C$12,MIN(5-$D4+1,5)))
A5: 4 | B5: Sugarcane side-selling/verification | C5: A. Agriculture | D5: 4 | E5: 40000000 | F5: =IF(1<$D5,0,$E5*Assumptions!$C$4*INDEX(Assumptions!$C$8:$C$12,MIN(1-$D5+1,5))) | G5: =IF(2<$D5,0,$E5*Assumptions!$C$4*INDEX(Assumptions!$C$8:$C$12,MIN(2-$D5+1,5))) | H5: =IF(3<$D5,0,$E5*Assumptions!$C$4*INDEX(Assumptions!$C$8:$C$12,MIN(3-$D5+1,5))) | I5: =IF(4<$D5,0,$E5*Assumptions!$C$4*INDEX(Assumptions!$C$8:$C$12,MIN(4-$D5+1,5))) | J5: =IF(5<$D5,0,$E5*Assumptions!$C$4*INDEX(Assumptions!$C$8:$C$12,MIN(5-$D5+1,5)))
A6: 5 | B6: Horticulture — cut flowers | C6: A. Agriculture | D6: 2 | E6: 150000000 | F6: =IF(1<$D6,0,$E6*Assumptions!$C$4*INDEX(Assumptions!$C$8:$C$12,MIN(1-$D6+1,5))) | G6: =IF(2<$D6,0,$E6*Assumptions!$C$4*INDEX(Assumptions!$C$8:$C$12,MIN(2-$D6+1,5))) | H6: =IF(3<$D6,0,$E6*Assumptions!$C$4*INDEX(Assumptions!$C$8:$C$12,MIN(3-$D6+1,5))) | I6: =IF(4<$D6,0,$E6*Assumptions!$C$4*INDEX(Assumptions!$C$8:$C$12,MIN(4-$D6+1,5))) | J6: =IF(5<$D6,0,$E6*Assumptions!$C$4*INDEX(Assumptions!$C$8:$C$12,MIN(5-$D6+1,5)))
A7: 6 | B7: Horticulture — avocado | C7: A. Agriculture | D7: 2 | E7: 100000000 | F7: =IF(1<$D7,0,$E7*Assumptions!$C$4*INDEX(Assumptions!$C$8:$C$12,MIN(1-$D7+1,5))) | G7: =IF(2<$D7,0,$E7*Assumptions!$C$4*INDEX(Assumptions!$C$8:$C$12,MIN(2-$D7+1,5))) | H7: =IF(3<$D7,0,$E7*Assumptions!$C$4*INDEX(Assumptions!$C$8:$C$12,MIN(3-$D7+1,5))) | I7: =IF(4<$D7,0,$E7*Assumptions!$C$4*INDEX(Assumptions!$C$8:$C$12,MIN(4-$D7+1,5))) | J7: =IF(5<$D7,0,$E7*Assumptions!$C$4*INDEX(Assumptions!$C$8:$C$12,MIN(5-$D7+1,5)))
A8: 7 | B8: Horticulture — macadamia | C8: A. Agriculture | D8: 3 | E8: 70000000 | F8: =IF(1<$D8,0,$E8*Assumptions!$C$4*INDEX(Assumptions!$C$8:$C$12,MIN(1-$D8+1,5))) | G8: =IF(2<$D8,0,$E8*Assumptions!$C$4*INDEX(Assumptions!$C$8:$C$12,MIN(2-$D8+1,5))) | H8: =IF(3<$D8,0,$E8*Assumptions!$C$4*INDEX(Assumptions!$C$8:$C$12,MIN(3-$D8+1,5))) | I8: =IF(4<$D8,0,$E8*Assumptions!$C$4*INDEX(Assumptions!$C$8:$C$12,MIN(4-$D8+1,5))) | J8: =IF(5<$D8,0,$E8*Assumptions!$C$4*INDEX(Assumptions!$C$8:$C$12,MIN(5-$D8+1,5)))
A9: 8 | B9: Horticulture — French beans/veg | C9: A. Agriculture | D9: 3 | E9: 60000000 | F9: =IF(1<$D9,0,$E9*Assumptions!$C$4*INDEX(Assumptions!$C$8:$C$12,MIN(1-$D9+1,5))) | G9: =IF(2<$D9,0,$E9*Assumptions!$C$4*INDEX(Assumptions!$C$8:$C$12,MIN(2-$D9+1,5))) | H9: =IF(3<$D9,0,$E9*Assumptions!$C$4*INDEX(Assumptions!$C$8:$C$12,MIN(3-$D9+1,5))) | I9: =IF(4<$D9,0,$E9*Assumptions!$C$4*INDEX(Assumptions!$C$8:$C$12,MIN(4-$D9+1,5))) | J9: =IF(5<$D9,0,$E9*Assumptions!$C$4*INDEX(Assumptions!$C$8:$C$12,MIN(5-$D9+1,5)))
A10: 9 | B10: Livestock & dairy | C10: A. Agriculture | D10: 2 | E10: 80000000 | F10: =IF(1<$D10,0,$E10*Assumptions!$C$4*INDEX(Assumptions!$C$8:$C$12,MIN(1-$D10+1,5))) | G10: =IF(2<$D10,0,$E10*Assumptions!$C$4*INDEX(Assumptions!$C$8:$C$12,MIN(2-$D10+1,5))) | H10: =IF(3<$D10,0,$E10*Assumptions!$C$4*INDEX(Assumptions!$C$8:$C$12,MIN(3-$D10+1,5))) | I10: =IF(4<$D10,0,$E10*Assumptions!$C$4*INDEX(Assumptions!$C$8:$C$12,MIN(4-$D10+1,5))) | J10: =IF(5<$D10,0,$E10*Assumptions!$C$4*INDEX(Assumptions!$C$8:$C$12,MIN(5-$D10+1,5)))
A11: 10 | B11: Poultry | C11: A. Agriculture | D11: 3 | E11: 40000000 | F11: =IF(1<$D11,0,$E11*Assumptions!$C$4*INDEX(Assumptions!$C$8:$C$12,MIN(1-$D11+1,5))) | G11: =IF(2<$D11,0,$E11*Assumptions!$C$4*INDEX(Assumptions!$C$8:$C$12,MIN(2-$D11+1,5))) | H11: =IF(3<$D11,0,$E11*Assumptions!$C$4*INDEX(Assumptions!$C$8:$C$12,MIN(3-$D11+1,5))) | I11: =IF(4<$D11,0,$E11*Assumptions!$C$4*INDEX(Assumptions!$C$8:$C$12,MIN(4-$D11+1,5))) | J11: =IF(5<$D11,0,$E11*Assumptions!$C$4*INDEX(Assumptions!$C$8:$C$12,MIN(5-$D11+1,5)))
A12: 11 | B12: Cotton (feeds Pipeline 22) | C12: A. Agriculture | D12: 4 | E12: 15000000 | F12: =IF(1<$D12,0,$E12*Assumptions!$C$4*INDEX(Assumptions!$C$8:$C$12,MIN(1-$D12+1,5))) | G12: =IF(2<$D12,0,$E12*Assumptions!$C$4*INDEX(Assumptions!$C$8:$C$12,MIN(2-$D12+1,5))) | H12: =IF(3<$D12,0,$E12*Assumptions!$C$4*INDEX(Assumptions!$C$8:$C$12,MIN(3-$D12+1,5))) | I12: =IF(4<$D12,0,$E12*Assumptions!$C$4*INDEX(Assumptions!$C$8:$C$12,MIN(4-$D12+1,5))) | J12: =IF(5<$D12,0,$E12*Assumptions!$C$4*INDEX(Assumptions!$C$8:$C$12,MIN(5-$D12+1,5)))
A13: 12 | B13: Fisheries & blue economy | C13: A. Agriculture | D13: 3 | E13: 50000000 | F13: =IF(1<$D13,0,$E13*Assumptions!$C$4*INDEX(Assumptions!$C$8:$C$12,MIN(1-$D13+1,5))) | G13: =IF(2<$D13,0,$E13*Assumptions!$C$4*INDEX(Assumptions!$C$8:$C$12,MIN(2-$D13+1,5))) | H13: =IF(3<$D13,0,$E13*Assumptions!$C$4*INDEX(Assumptions!$C$8:$C$12,MIN(3-$D13+1,5))) | I13: =IF(4<$D13,0,$E13*Assumptions!$C$4*INDEX(Assumptions!$C$8:$C$12,MIN(4-$D13+1,5))) | J13: =IF(5<$D13,0,$E13*Assumptions!$C$4*INDEX(Assumptions!$C$8:$C$12,MIN(5-$D13+1,5)))
... A88: 87 | B88: Bulk trade brokerage | C88: M. Flagship & Investment | D88: 5 | E88: 60000000 | F88: =IF(1<$D88,0,$E88*Assumptions!$C$4*INDEX(Assumptions!$C$8:$C$12,MIN(1-$D88+1,5))) | G88: =IF(2<$D88,0,$E88*Assumptions!$C$4*INDEX(Assumptions!$C$8:$C$12,MIN(2-$D88+1,5))) | H88: =IF(3<$D88,0,$E88*Assumptions!$C$4*INDEX(Assumptions!$C$8:$C$12,MIN(3-$D88+1,5))) | I88: =IF(4<$D88,0,$E88*Assumptions!$C$4*INDEX(Assumptions!$C$8:$C$12,MIN(4-$D88+1,5))) | J88: =IF(5<$D88,0,$E88*Assumptions!$C$4*INDEX(Assumptions!$C$8:$C$12,MIN(5-$D88+1,5)))
B90: TOTAL — all 87 pipelines (KSh/yr) | F90: =SUM(F2:F88) | G90: =SUM(G2:G88) | H90: =SUM(H2:H88) | I90: =SUM(I2:I88) | J90: =SUM(J2:J88)

Sheet Category Summary
A1: Category | B1: Year 1 (KSh) | C1: Year 2 (KSh) | D1: Year 3 (KSh) | E1: Year 4 (KSh) | F1: Year 5 (KSh) | G1: 5-Yr CAGR
A2: A. Agriculture | B2: =SUMIFS('Pipeline Model'!F$2:F$88,'Pipeline Model'!$C$2:$C$88,$A2) | C2: =SUMIFS('Pipeline Model'!G$2:G$88,'Pipeline Model'!$C$2:$C$88,$A2) | D2: =SUMIFS('Pipeline Model'!H$2:H$88,'Pipeline Model'!$C$2:$C$88,$A2) | E2: =SUMIFS('Pipeline Model'!I$2:I$88,'Pipeline Model'!$C$2:$C$88,$A2) | F2: =SUMIFS('Pipeline Model'!J$2:J$88,'Pipeline Model'!$C$2:$C$88,$A2) | G2: =IFERROR((F2/B2)^(1/4)-1,"n/m")
A3: B. Minerals | B3: =SUMIFS('Pipeline Model'!F$2:F$88,'Pipeline Model'!$C$2:$C$88,$A3) | C3: =SUMIFS('Pipeline Model'!G$2:G$88,'Pipeline Model'!$C$2:$C$88,$A3) | D3: =SUMIFS('Pipeline Model'!H$2:H$88,'Pipeline Model'!$C$2:$C$88,$A3) | E3: =SUMIFS('Pipeline Model'!I$2:I$88,'Pipeline Model'!$C$2:$C$88,$A3) | F3: =SUMIFS('Pipeline Model'!J$2:J$88,'Pipeline Model'!$C$2:$C$88,$A3) | G3: =IFERROR((F3/B3)^(1/4)-1,"n/m")
A4: C. Industrial & SEZ | B4: =SUMIFS('Pipeline Model'!F$2:F$88,'Pipeline Model'!$C$2:$C$88,$A4) | C4: =SUMIFS('Pipeline Model'!G$2:G$88,'Pipeline Model'!$C$2:$C$88,$A4) | D4: =SUMIFS('Pipeline Model'!H$2:H$88,'Pipeline Model'!$C$2:$C$88,$A4) | E4: =SUMIFS('Pipeline Model'!I$2:I$88,'Pipeline Model'!$C$2:$C$88,$A4) | F4: =SUMIFS('Pipeline Model'!J$2:J$88,'Pipeline Model'!$C$2:$C$88,$A4) | G4: =IFERROR((F4/B4)^(1/4)-1,"n/m")
A5: D. Energy & Infra | B5: =SUMIFS('Pipeline Model'!F$2:F$88,'Pipeline Model'!$C$2:$C$88,$A5) | C5: =SUMIFS('Pipeline Model'!G$2:G$88,'Pipeline Model'!$C$2:$C$88,$A5) | D5: =SUMIFS('Pipeline Model'!H$2:H$88,'Pipeline Model'!$C$2:$C$88,$A5) | E5: =SUMIFS('Pipeline Model'!I$2:I$88,'Pipeline Model'!$C$2:$C$88,$A5) | F5: =SUMIFS('Pipeline Model'!J$2:J$88,'Pipeline Model'!$C$2:$C$88,$A5) | G5: =IFERROR((F5/B5)^(1/4)-1,"n/m")
A6: E. Real Estate | B6: =SUMIFS('Pipeline Model'!F$2:F$88,'Pipeline Model'!$C$2:$C$88,$A6) | C6: =SUMIFS('Pipeline Model'!G$2:G$88,'Pipeline Model'!$C$2:$C$88,$A6) | D6: =SUMIFS('Pipeline Model'!H$2:H$88,'Pipeline Model'!$C$2:$C$88,$A6) | E6: =SUMIFS('Pipeline Model'!I$2:I$88,'Pipeline Model'!$C$2:$C$88,$A6) | F6: =SUMIFS('Pipeline Model'!J$2:J$88,'Pipeline Model'!$C$2:$C$88,$A6) | G6: =IFERROR((F6/B6)^(1/4)-1,"n/m")
A7: F. Tourism | B7: =SUMIFS('Pipeline Model'!F$2:F$88,'Pipeline Model'!$C$2:$C$88,$A7) | C7: =SUMIFS('Pipeline Model'!G$2:G$88,'Pipeline Model'!$C$2:$C$88,$A7) | D7: =SUMIFS('Pipeline Model'!H$2:H$88,'Pipeline Model'!$C$2:$C$88,$A7) | E7: =SUMIFS('Pipeline Model'!I$2:I$88,'Pipeline Model'!$C$2:$C$88,$A7) | F7: =SUMIFS('Pipeline Model'!J$2:J$88,'Pipeline Model'!$C$2:$C$88,$A7) | G7: =IFERROR((F7/B7)^(1/4)-1,"n/m")
A8: G. Commerce & Discovery | B8: =SUMIFS('Pipeline Model'!F$2:F$88,'Pipeline Model'!$C$2:$C$88,$A8) | C8: =SUMIFS('Pipeline Model'!G$2:G$88,'Pipeline Model'!$C$2:$C$88,$A8) | D8: =SUMIFS('Pipeline Model'!H$2:H$88,'Pipeline Model'!$C$2:$C$88,$A8) | E8: =SUMIFS('Pipeline Model'!I$2:I$88,'Pipeline Model'!$C$2:$C$88,$A8) | F8: =SUMIFS('Pipeline Model'!J$2:J$88,'Pipeline Model'!$C$2:$C$88,$A8) | G8: =IFERROR((F8/B8)^(1/4)-1,"n/m")
A9: H. Logistics | B9: =SUMIFS('Pipeline Model'!F$2:F$88,'Pipeline Model'!$C$2:$C$88,$A9) | C9: =SUMIFS('Pipeline Model'!G$2:G$88,'Pipeline Model'!$C$2:$C$88,$A9) | D9: =SUMIFS('Pipeline Model'!H$2:H$88,'Pipeline Model'!$C$2:$C$88,$A9) | E9: =SUMIFS('Pipeline Model'!I$2:I$88,'Pipeline Model'!$C$2:$C$88,$A9) | F9: =SUMIFS('Pipeline Model'!J$2:J$88,'Pipeline Model'!$C$2:$C$88,$A9) | G9: =IFERROR((F9/B9)^(1/4)-1,"n/m")
A10: I. Financial Services | B10: =SUMIFS('Pipeline Model'!F$2:F$88,'Pipeline Model'!$C$2:$C$88,$A10) | C10: =SUMIFS('Pipeline Model'!G$2:G$88,'Pipeline Model'!$C$2:$C$88,$A10) | D10: =SUMIFS('Pipeline Model'!H$2:H$88,'Pipeline Model'!$C$2:$C$88,$A10) | E10: =SUMIFS('Pipeline Model'!I$2:I$88,'Pipeline Model'!$C$2:$C$88,$A10) | F10: =SUMIFS('Pipeline Model'!J$2:J$88,'Pipeline Model'!$C$2:$C$88,$A10) | G10: =IFERROR((F10/B10)^(1/4)-1,"n/m")
A11: J. Government | B11: =SUMIFS('Pipeline Model'!F$2:F$88,'Pipeline Model'!$C$2:$C$88,$A11) | C11: =SUMIFS('Pipeline Model'!G$2:G$88,'Pipeline Model'!$C$2:$C$88,$A11) | D11: =SUMIFS('Pipeline Model'!H$2:H$88,'Pipeline Model'!$C$2:$C$88,$A11) | E11: =SUMIFS('Pipeline Model'!I$2:I$88,'Pipeline Model'!$C$2:$C$88,$A11) | F11: =SUMIFS('Pipeline Model'!J$2:J$88,'Pipeline Model'!$C$2:$C$88,$A11) | G11: =IFERROR((F11/B11)^(1/4)-1,"n/m")
A12: K. Additional Sectors | B12: =SUMIFS('Pipeline Model'!F$2:F$88,'Pipeline Model'!$C$2:$C$88,$A12) | C12: =SUMIFS('Pipeline Model'!G$2:G$88,'Pipeline Model'!$C$2:$C$88,$A12) | D12: =SUMIFS('Pipeline Model'!H$2:H$88,'Pipeline Model'!$C$2:$C$88,$A12) | E12: =SUMIFS('Pipeline Model'!I$2:I$88,'Pipeline Model'!$C$2:$C$88,$A12) | F12: =SUMIFS('Pipeline Model'!J$2:J$88,'Pipeline Model'!$C$2:$C$88,$A12) | G12: =IFERROR((F12/B12)^(1/4)-1,"n/m")
A13: L. RE Rental Expansion | B13: =SUMIFS('Pipeline Model'!F$2:F$88,'Pipeline Model'!$C$2:$C$88,$A13) | C13: =SUMIFS('Pipeline Model'!G$2:G$88,'Pipeline Model'!$C$2:$C$88,$A13) | D13: =SUMIFS('Pipeline Model'!H$2:H$88,'Pipeline Model'!$C$2:$C$88,$A13) | E13: =SUMIFS('Pipeline Model'!I$2:I$88,'Pipeline Model'!$C$2:$C$88,$A13) | F13: =SUMIFS('Pipeline Model'!J$2:J$88,'Pipeline Model'!$C$2:$C$88,$A13) | G13: =IFERROR((F13/B13)^(1/4)-1,"n/m")
A14: M. Flagship & Investment | B14: =SUMIFS('Pipeline Model'!F$2:F$88,'Pipeline Model'!$C$2:$C$88,$A14) | C14: =SUMIFS('Pipeline Model'!G$2:G$88,'Pipeline Model'!$C$2:$C$88,$A14) | D14: =SUMIFS('Pipeline Model'!H$2:H$88,'Pipeline Model'!$C$2:$C$88,$A14) | E14: =SUMIFS('Pipeline Model'!I$2:I$88,'Pipeline Model'!$C$2:$C$88,$A14) | F14: =SUMIFS('Pipeline Model'!J$2:J$88,'Pipeline Model'!$C$2:$C$88,$A14) | G14: =IFERROR((F14/B14)^(1/4)-1,"n/m")
A15: TOTAL | B15: =SUM(B2:B14) | C15: =SUM(C2:C14) | D15: =SUM(D2:D14) | E15: =SUM(E2:E14) | F15: =SUM(F2:F14)

Sheet Advertising & Media Cost
A1: Advertising & Media Cost by Sector — Screentime vs Airtime (KES)
A2: Marketing cost = sector gross revenue x marketing-to-revenue ratio (14%, 11%, 9%, 7%, 6% in Years 1-5), split by channel mix. Figures are rounded to whole Kenya Shillings and each row reconciles to its total.
A3: Sector | B3: Screentime % | C3: Airtime % | D3: Year 1 Total | E3: Year 1 Screentime | F3: Year 1 Airtime | G3: Year 2 Total | H3: Year 2 Screentime | I3: Year 2 Airtime | J3: Year 3 Total | K3: Year 3 Screentime | L3: Year 3 Airtime | M3: Year 4 Total | N3: Year 4 Screentime | O3: Year 4 Airtime | P3: Year 5 Total | Q3: Year 5 Screentime | R3: Year 5 Airtime
A4: A. Agriculture | B4: 0.3 | C4: 0.7 | D4: 0 | E4: 0 | F4: 0 | G4: 13365000 | H4: 4009500 | I4: 9355500 | J4: 38475000 | K4: 11542500 | L4: 26932500 | M4: 58275000 | N4: 17482500 | O4: 40792500 | P4: 71550000 | Q4: 21465000 | R4: 50085000
A5: B. Minerals | B5: 0.4 | C5: 0.6 | D5: 0 | E5: 0 | F5: 0 | G5: 0 | H5: 0 | I5: 0 | J5: 5568750 | K5: 2227500 | L5: 3341250 | M5: 13119750 | N5: 5247900 | O5: 7871850 | P5: 18886500 | Q5: 7554600 | R5: 11331900
A6: C. Industrial & SEZ | B6: 0.6 | C6: 0.4 | D6: 0 | E6: 0 | F6: 0 | G6: 618750 | H6: 371250 | I6: 247500 | J6: 3442500 | K6: 2065500 | L6: 1377000 | M6: 6772500 | N6: 4063500 | O6: 2709000 | P6: 9360000 | Q6: 5616000 | R6: 3744000
A7: D. Energy & Infra | B7: 0.55 | C7: 0.45 | D7: 0 | E7: 0 | F7: 0 | G7: 0 | H7: 0 | I7: 0 | J7: 0 | K7: 0 | L7: 0 | M7: 1181250 | N7: 649687 | O7: 531563 | P7: 3172500 | Q7: 1744875 | R7: 1427625
A8: E. Real Estate | B8: 0.7 | C8: 0.3 | D8: 6930000 | E8: 4851000 | F8: 2079000 | G8: 18438750 | H8: 12907125 | I8: 5531625 | J8: 27438750 | K8: 19207125 | L8: 8231625 | M8: 28638750 | N8: 20047125 | O8: 8591625 | P8: 27067500 | Q8: 18947250 | R8: 8120250
A9: F. Tourism | B9: 0.75 | C9: 0.25 | D9: 11025000 | E9: 8268750 | F9: 2756250 | G9: 28462500 | H9: 21346875 | I9: 7115625 | J9: 43031250 | K9: 32273437 | L9: 10757813 | M9: 46331250 | N9: 34748437 | O9: 11582813 | P9: 45112500 | Q9: 33834375 | R9: 11278125
A10: G. Commerce & Discovery | B10: 0.65 | C10: 0.35 | D10: 15277500 | E10: 9930375 | F10: 5347125 | G10: 36011250 | H10: 23407312 | I10: 12603938 | J10: 50220000 | K10: 32643000 | L10: 17577000 | M10: 50977500 | N10: 33135375 | O10: 17842125 | P10: 47362500 | Q10: 30785625 | R10: 16576875
A11: H. Logistics | B11: 0.5 | C11: 0.5 | D11: 0 | E11: 0 | F11: 0 | G11: 0 | H11: 0 | I11: 0 | J11: 2936250 | K11: 1468125 | L11: 1468125 | M11: 6851250 | N11: 3425625 | O11: 3425625 | P11: 9787500 | Q11: 4893750 | R11: 4893750
A12: I. Financial Services | B12: 0.6 | C12: 0.4 | D12: 0 | E12: 0 | F12: 0 | G12: 1237500 | H12: 742500 | I12: 495000 | J12: 3037500 | K12: 1822500 | L12: 1215000 | M12: 5827500 | N12: 3496500 | O12: 2331000 | P12: 9945000 | Q12: 5967000 | R12: 3978000
A13: J. Government | B13: 0.35 | C13: 0.65 | D13: 472500 | E13: 165375 | F13: 307125 | G13: 2846250 | H13: 996187 | I13: 1850063 | J13: 5771250 | K13: 2019937 | L13: 3751313 | M13: 7008750 | N13: 2453062 | O13: 4555688 | P13: 7335000 | Q13: 2567250 | R13: 4767750
A14: K. Additional Sectors | B14: 0.5 | C14: 0.5 | D14: 0 | E14: 0 | F14: 0 | G14: 0 | H14: 0 | I14: 0 | J14: 1417500 | K14: 708750 | L14: 708750 | M14: 4410000 | N14: 2205000 | O14: 2205000 | P14: 7560000 | Q14: 3780000 | R14: 3780000
A15: L. RE Rental Expansion | B15: 0.7 | C15: 0.3 | D15: 0 | E15: 0 | F15: 0 | G15: 6930000 | H15: 4851000 | I15: 2079000 | J15: 17010000 | K15: 11907000 | L15: 5103000 | M15: 22050000 | N15: 15435000 | O15: 6615000 | P15: 23940000 | Q15: 16758000 | R15: 7182000
A16: M. Flagship & Investment | B16: 0.65 | C16: 0.35 | D16: 0 | E16: 0 | F16: 0 | G16: 0 | H16: 0 | I16: 0 | J16: 0 | K16: 0 | L16: 0 | M16: 1417500 | N16: 921375 | O16: 496125 | P16: 5737500 | Q16: 3729375 | R16: 2008125
A17: TOTAL | D17: 33705000 | E17: 23215500 | F17: 10489500 | G17: 107910000 | H17: 68631749 | I17: 39278251 | J17: 198348750 | K17: 117885374 | L17: 80463376 | M17: 252861000 | N17: 143311086 | O17: 109549914 | P17: 286816500 | Q17: 157643100 | R17: 129173400
A19: Five-year totals (Years 1-5)
A20: Total advertising & media | B20: 879641250
A21: Of which screentime | B21: 510686809
A22: Of which airtime | B22: 368954441

Sheet Media Rate Card
A1: Media Rate Card — Prevailing Kenyan Market Rates (KES)
A2: Reference benchmarks for media procurement. Contract rates are negotiated against these figures.
A4: Screentime | B4: Unit | C4: Rate (KES)
A5: National terrestrial TV, prime-time 30-second spot | B5: per spot | C5: 450,000 - 800,000
A6: National TV, off-peak 30-second spot | B6: per spot | C6: 150,000 - 350,000
A7: Regional and vernacular TV, 30-second spot | B7: per spot | C7: 40,000 - 120,000
A8: Large-format billboard, Nairobi metro | B8: per panel per month | C8: 250,000 - 650,000
A9: County-town billboard | B9: per panel per month | C9: 80,000 - 250,000
A10: Digital out-of-home screen (mall and fuel-station networks) | B10: per screen per month | C10: 35,000 - 120,000
A11: Digital display and video | B11: cost per 1,000 impressions | C11: 300 - 900
A12: Cinema, 30-second spot | B12: per screen per week | C12: 45,000 - 150,000
A14: Airtime | B14: Unit | C14: Rate (KES)
A15: National radio, prime-time 30-second spot | B15: per spot | C15: 30,000 - 95,000
A16: Vernacular radio, 30-second spot | B16: per spot | C16: 8,000 - 35,000
... A21: Digital audio (streaming and podcast) | B21: cost per 1,000 impressions | C21: 250 - 700

Sheet Full Maturity
A1: Full-Maturity Position (Year 7 stabilised)
A2: All 87 pipelines at 100% of steady-state x 1.5 scale factor.
A3: Gross revenue per year | B3: 5974500000
A4: Advertising & media cost per year (6% of revenue) | B4: 358470000
A5: Net revenue per year | B5: 5616030000
A6: Net run-rate per month | B6: 468002500
A7: Equivalent USD per month (at KES 129) | B7: 3627926
A8: Gross maturity by category
A9: Agriculture | B9: 1470000000
A10: Commerce & Discovery | B10: 810000000
A11: Tourism | B11: 787500000
A12: Real Estate | B12: 457500000
A13: Minerals | B13: 424500000
A14: RE Rental Expansion | B14: 420000000
A15: Flagship & Investment | B15: 367500000
A16: Financial Services | B16: 345000000
A17: Logistics | B17: 217500000
A18: Industrial & SEZ | B18: 210000000
A19: Additional Sectors | B19: 210000000
A20: Energy & Infra | B20: 127500000
A21: Government | B21: 127500000
