Workbook

Sheet Executive Summary
A1: KICC — 87-Pipeline Revenue Model: Executive Summary
A2: Phased-launch, ramp-adjusted projection across all 87 catalog pipelines, net of advertising & media cost. Figures are modeled estimates — see Assumptions tab.
A4: Year | B4: Year 1 | C4: Year 2 | D4: Year 3 | E4: Year 4 | F4: Year 5
A5: Gross revenue (KSh/yr) | B5: ='Pipeline Model'!F90 -> 240750000 | C5: ='Pipeline Model'!G90 -> 981000000 | D5: ='Pipeline Model'!H90 -> 2203875000 | E5: ='Pipeline Model'!I90 -> 3612300000 | F5: ='Pipeline Model'!J90 -> 4780275000
A6: Less: advertising & media cost (KSh/yr) | B6: =-'Advertising & Media Cost'!D18 -> -33705000 | C6: =-'Advertising & Media Cost'!G18 -> -107910000 | D6: =-'Advertising & Media Cost'!J18 -> -198348750 | E6: =-'Advertising & Media Cost'!M18 -> -252861000 | F6: =-'Advertising & Media Cost'!P18 -> -286816500
A7: of which: Screentime (TV/digital/OOH) | B7: ='Advertising & Media Cost'!E18 -> 23215500 | C7: ='Advertising & Media Cost'!H18 -> 68631750 | D7: ='Advertising & Media Cost'!K18 -> 117885375 | E7: ='Advertising & Media Cost'!N18 -> 1.4331109e+08 | F7: ='Advertising & Media Cost'!Q18 -> 157643100
A8: of which: Airtime (radio/mobile) | B8: ='Advertising & Media Cost'!F18 -> 10489500 | C8: ='Advertising & Media Cost'!I18 -> 39278250 | D8: ='Advertising & Media Cost'!L18 -> 80463375 | E8: ='Advertising & Media Cost'!O18 -> 1.0954991e+08 | F8: ='Advertising & Media Cost'!R18 -> 129173400
A9: Net revenue after advertising (KSh/yr) | B9: =B5+B6 -> 207045000 | C9: =C5+C6 -> 873090000 | D9: =D5+D6 -> 2005526250 | E9: =E5+E6 -> 3359439000 | F9: =F5+F6 -> 4493458500
A10: Net revenue after advertising (USD/yr) | B10: =B9/Assumptions!$C$3 -> 1605000 | C10: =C9/Assumptions!$C$3 -> 6768139.5 | D10: =D9/Assumptions!$C$3 -> 15546715 | E10: =E9/Assumptions!$C$3 -> 26042163 | F10: =F9/Assumptions!$C$3 -> 34833012
A11: Net run-rate at year-end (USD/month) | B11: =B10/12 -> 133750 | C11: =C10/12 -> 564011.63 | D11: =D10/12 -> 1295559.6 | E11: =E10/12 -> 2170180.2 | F11: =F10/12 -> 2902751
A12: Target run-rate (USD/month) | B12: 12000000 | C12: 12000000 | D12: 12000000 | E12: 12000000 | F12: 12000000
A13: Gap to target (USD/month) | B13: =B11-B12 -> -11866250 | C13: =C11-C12 -> -11435988 | D13: =D11-D12 -> -10704440 | E13: =E11-E12 -> -9829819.8 | F13: =F11-F12 -> -9097249
A15: Key takeaways
A16: - Revenue compounds as later-wave pipelines (minerals, energy, financial services, flagship/investment) come
A17: online and earlier waves (real estate, tourism, marketplace) mature past their ramp period.
A18: - Advertising & media cost (screentime + airtime) is modeled as a declining share of revenue — KSh 33.7 million
A19: in Year 1 rising to KSh 286.8 million in Year 5 — and is deducted before the net run-rate figures above.
A20: - Even net of advertising cost, the model lands short of a $12,000,000/month steady-state target by Year 5 —
A21: the honest ceiling given realistic adoption ramps, not a shortfall to be closed by adding more pipelines.
A22: - Minerals, Energy, and Flagship/Investment lines are back-loaded (Year 3-5 launch) and licence/regulation-
A23: gated in places (direct lending, equity), so they carry the most execution and regulatory risk in the model.

Sheet Assumptions
A1: KICC 87-Pipeline Revenue Model — Assumptions & Methodology
B3: FX rate (KSh per USD) | C3: 129 | D3: Input — update to current CBK reference rate
B4: Uniform scale factor applied to base pipeline-size estimates | C4: 1.5 | D4: Input — sensitivity lever; see note below
B6: Adoption ramp curve (share of steady-state maturity revenue reached, by years since a pipeline's launch)
B7: Years since launch | C7: Ramp %
B8: 1 | C8: 0.15 | D8: Launch year itself: still ramping up (onboarding, trust-building)
B9: 2 | C9: 0.45
B10: 3 | C10: 0.75
B11: 4 | C11: 0.95
B12: 5 | C12: 1 | D12: Year 5+ since launch: treated as fully mature for this model
B14: Advertising & media spend — % of that year's revenue (economy-wide)
B15: Year | C15: Marketing % of revenue
B16: Year 1 | C16: 0.14 | D16: Declining spend-to-revenue ratio as the platform matures (word-of-mouth/repeat usage substitute for paid reach) — absolute KSh spend still grows with revenue.
B17: Year 2 | C17: 0.11
B18: Year 3 | C18: 0.09
B19: Year 4 | C19: 0.07
B20: Year 5 | C20: 0.06
B22: Advertising channel split by category — Screentime (TV, digital display/OOH, cinema) vs. Airtime (radio, mobile airtime/SMS, USSD)
B23: Category | C23: Screentime % | D23: Airtime %
B24: A. Agriculture | C24: 0.3 | D24: 0.7 | E24: Rural/smallholder-heavy categories skew to radio airtime; urban/digital-native categories skew to screentime.
B25: B. Minerals | C25: 0.4 | D25: 0.6
B26: C. Industrial & SEZ | C26: 0.6 | D26: 0.4
B27: D. Energy & Infra | C27: 0.55 | D27: 0.45
B28: E. Real Estate | C28: 0.7 | D28: 0.3
B29: F. Tourism | C29: 0.75 | D29: 0.25
B30: G. Commerce & Discovery | C30: 0.65 | D30: 0.35
B31: H. Logistics | C31: 0.5 | D31: 0.5
B32: I. Financial Services | C32: 0.6 | D32: 0.4
B33: J. Government | C33: 0.35 | D33: 0.65
B34: K. Additional Sectors | C34: 0.5 | D34: 0.5
B35: L. RE Rental Expansion | C35: 0.7 | D35: 0.3
B36: M. Flagship & Investment | C36: 0.65 | D36: 0.35
B38: Methodology notes
B39: 1. Each of the 87 pipelines in the catalog is assigned a category, a Launch Year (1-5), and a Steady-State
B40: Annual Revenue estimate at full maturity (KSh), on the 'Pipeline Model' sheet.
B41: 2. Steady-state values are MODELED ESTIMATES, not sourced third-party market sizing. They were derived from
B42: the qualitative scale signals in the pipeline catalog itself (e.g. 'largest single export earner' vs.
B43: 'early-stage/exploration', stated commission ranges). Replace with sourced sector data (KNBS, CBK, sector
B44: board reports) before this model is used for fundraising or budget commitments.
B45: 3. Revenue in any given year = Steady-State Value x Scale Factor x Ramp% for (current year - launch year).
...

Sheet Pipeline Model
A1: ID | B1: Pipeline | C1: Category | D1: Launch Year | E1: Steady-State Revenue at Maturity (KSh/yr) | F1: Year 1 (KSh) | G1: Year 2 (KSh) | H1: Year 3 (KSh) | I1: Year 4 (KSh) | J1: Year 5 (KSh)
A2: 1 | B2: Coffee aggregation & export match | C2: A. Agriculture | D2: 2 | E2: 120000000 | F2: =IF(1<$D2,0,$E2*Assumptions!$C$4*INDEX(Assumptions!$C$8:$C$12,MIN(1-$D2+1,5))) -> 0 | G2: =IF(2<$D2,0,$E2*Assumptions!$C$4*INDEX(Assumptions!$C$8:$C$12,MIN(2-$D2+1,5))) -> 27000000 | H2: =IF(3<$D2,0,$E2*Assumptions!$C$4*INDEX(Assumptions!$C$8:$C$12,MIN(3-$D2+1,5))) -> 81000000 | I2: =IF(4<$D2,0,$E2*Assumptions!$C$4*INDEX(Assumptions!$C$8:$C$12,MIN(4-$D2+1,5))) -> 135000000 | J2: =IF(5<$D2,0,$E2*Assumptions!$C$4*INDEX(Assumptions!$C$8:$C$12,MIN(5-$D2+1,5))) -> 171000000
A3: 2 | B3: Tea (non-KTDA / specialty) | C3: A. Agriculture | D3: 3 | E3: 60000000 | F3: =IF(1<$D3,0,$E3*Assumptions!$C$4*INDEX(Assumptions!$C$8:$C$12,MIN(1-$D3+1,5))) -> 0 | G3: =IF(2<$D3,0,$E3*Assumptions!$C$4*INDEX(Assumptions!$C$8:$C$12,MIN(2-$D3+1,5))) -> 0 | H3: =IF(3<$D3,0,$E3*Assumptions!$C$4*INDEX(Assumptions!$C$8:$C$12,MIN(3-$D3+1,5))) -> 13500000 | I3: =IF(4<$D3,0,$E3*Assumptions!$C$4*INDEX(Assumptions!$C$8:$C$12,MIN(4-$D3+1,5))) -> 40500000 | J3: =IF(5<$D3,0,$E3*Assumptions!$C$4*INDEX(Assumptions!$C$8:$C$12,MIN(5-$D3+1,5))) -> 67500000
A4: 3 | B4: Maize domestic distribution | C4: A. Agriculture | D4: 2 | E4: 90000000 | F4: =IF(1<$D4,0,$E4*Assumptions!$C$4*INDEX(Assumptions!$C$8:$C$12,MIN(1-$D4+1,5))) -> 0 | G4: =IF(2<$D4,0,$E4*Assumptions!$C$4*INDEX(Assumptions!$C$8:$C$12,MIN(2-$D4+1,5))) -> 20250000 | H4: =IF(3<$D4,0,$E4*Assumptions!$C$4*INDEX(Assumptions!$C$8:$C$12,MIN(3-$D4+1,5))) -> 60750000 | I4: =IF(4<$D4,0,$E4*Assumptions!$C$4*INDEX(Assumptions!$C$8:$C$12,MIN(4-$D4+1,5))) -> 101250000 | J4: =IF(5<$D4,0,$E4*Assumptions!$C$4*INDEX(Assumptions!$C$8:$C$12,MIN(5-$D4+1,5))) -> 128250000
A5: 4 | B5: Sugarcane side-selling/verification | C5: A. Agriculture | D5: 4 | E5: 40000000 | F5: =IF(1<$D5,0,$E5*Assumptions!$C$4*INDEX(Assumptions!$C$8:$C$12,MIN(1-$D5+1,5))) -> 0 | G5: =IF(2<$D5,0,$E5*Assumptions!$C$4*INDEX(Assumptions!$C$8:$C$12,MIN(2-$D5+1,5))) -> 0 | H5: =IF(3<$D5,0,$E5*Assumptions!$C$4*INDEX(Assumptions!$C$8:$C$12,MIN(3-$D5+1,5))) -> 0 | I5: =IF(4<$D5,0,$E5*Assumptions!$C$4*INDEX(Assumptions!$C$8:$C$12,MIN(4-$D5+1,5))) -> 9000000 | J5: =IF(5<$D5,0,$E5*Assumptions!$C$4*INDEX(Assumptions!$C$8:$C$12,MIN(5-$D5+1,5))) -> 27000000
A6: 5 | B6: Horticulture — cut flowers | C6: A. Agriculture | D6: 2 | E6: 150000000 | F6: =IF(1<$D6,0,$E6*Assumptions!$C$4*INDEX(Assumptions!$C$8:$C$12,MIN(1-$D6+1,5))) -> 0 | G6: =IF(2<$D6,0,$E6*Assumptions!$C$4*INDEX(Assumptions!$C$8:$C$12,MIN(2-$D6+1,5))) -> 33750000 | H6: =IF(3<$D6,0,$E6*Assumptions!$C$4*INDEX(Assumptions!$C$8:$C$12,MIN(3-$D6+1,5))) -> 101250000 | I6: =IF(4<$D6,0,$E6*Assumptions!$C$4*INDEX(Assumptions!$C$8:$C$12,MIN(4-$D6+1,5))) -> 168750000 | J6: =IF(5<$D6,0,$E6*Assumptions!$C$4*INDEX(Assumptions!$C$8:$C$12,MIN(5-$D6+1,5))) -> 213750000
A7: 6 | B7: Horticulture — avocado | C7: A. Agriculture | D7: 2 | E7: 100000000 | F7: =IF(1<$D7,0,$E7*Assumptions!$C$4*INDEX(Assumptions!$C$8:$C$12,MIN(1-$D7+1,5))) -> 0 | G7: =IF(2<$D7,0,$E7*Assumptions!$C$4*INDEX(Assumptions!$C$8:$C$12,MIN(2-$D7+1,5))) -> 22500000 | H7: =IF(3<$D7,0,$E7*Assumptions!$C$4*INDEX(Assumptions!$C$8:$C$12,MIN(3-$D7+1,5))) -> 67500000 | I7: =IF(4<$D7,0,$E7*Assumptions!$C$4*INDEX(Assumptions!$C$8:$C$12,MIN(4-$D7+1,5))) -> 112500000 | J7: =IF(5<$D7,0,$E7*Assumptions!$C$4*INDEX(Assumptions!$C$8:$C$12,MIN(5-$D7+1,5))) -> 142500000
A8: 7 | B8: Horticulture — macadamia | C8: A. Agriculture | D8: 3 | E8: 70000000 | F8: =IF(1<$D8,0,$E8*Assumptions!$C$4*INDEX(Assumptions!$C$8:$C$12,MIN(1-$D8+1,5))) -> 0 | G8: =IF(2<$D8,0,$E8*Assumptions!$C$4*INDEX(Assumptions!$C$8:$C$12,MIN(2-$D8+1,5))) -> 0 | H8: =IF(3<$D8,0,$E8*Assumptions!$C$4*INDEX(Assumptions!$C$8:$C$12,MIN(3-$D8+1,5))) -> 15750000 | I8: =IF(4<$D8,0,$E8*Assumptions!$C$4*INDEX(Assumptions!$C$8:$C$12,MIN(4-$D8+1,5))) -> 47250000 | J8: =IF(5<$D8,0,$E8*Assumptions!$C$4*INDEX(Assumptions!$C$8:$C$12,MIN(5-$D8+1,5))) -> 78750000
A9: 8 | B9: Horticulture — French beans/veg | C9: A. Agriculture | D9: 3 | E9: 60000000 | F9: =IF(1<$D9,0,$E9*Assumptions!$C$4*INDEX(Assumptions!$C$8:$C$12,MIN(1-$D9+1,5))) -> 0 | G9: =IF(2<$D9,0,$E9*Assumptions!$C$4*INDEX(Assumptions!$C$8:$C$12,MIN(2-$D9+1,5))) -> 0 | H9: =IF(3<$D9,0,$E9*Assumptions!$C$4*INDEX(Assumptions!$C$8:$C$12,MIN(3-$D9+1,5))) -> 13500000 | I9: =IF(4<$D9,0,$E9*Assumptions!$C$4*INDEX(Assumptions!$C$8:$C$12,MIN(4-$D9+1,5))) -> 40500000 | J9: =IF(5<$D9,0,$E9*Assumptions!$C$4*INDEX(Assumptions!$C$8:$C$12,MIN(5-$D9+1,5))) -> 67500000
A10: 9 | B10: Livestock & dairy | C10: A. Agriculture | D10: 2 | E10: 80000000 | F10: =IF(1<$D10,0,$E10*Assumptions!$C$4*INDEX(Assumptions!$C$8:$C$12,MIN(1-$D10+1,5))) -> 0 | G10: =IF(2<$D10,0,$E10*Assumptions!$C$4*INDEX(Assumptions!$C$8:$C$12,MIN(2-$D10+1,5))) -> 18000000 | H10: =IF(3<$D10,0,$E10*Assumptions!$C$4*INDEX(Assumptions!$C$8:$C$12,MIN(3-$D10+1,5))) -> 54000000 | I10: =IF(4<$D10,0,$E10*Assumptions!$C$4*INDEX(Assumptions!$C$8:$C$12,MIN(4-$D10+1,5))) -> 90000000 | J10: =IF(5<$D10,0,$E10*Assumptions!$C$4*INDEX(Assumptions!$C$8:$C$12,MIN(5-$D10+1,5))) -> 114000000
A11: 10 | B11: Poultry | C11: A. Agriculture | D11: 3 | E11: 40000000 | F11: =IF(1<$D11,0,$E11*Assumptions!$C$4*INDEX(Assumptions!$C$8:$C$12,MIN(1-$D11+1,5))) -> 0 | G11: =IF(2<$D11,0,$E11*Assumptions!$C$4*INDEX(Assumptions!$C$8:$C$12,MIN(2-$D11+1,5))) -> 0 | H11: =IF(3<$D11,0,$E11*Assumptions!$C$4*INDEX(Assumptions!$C$8:$C$12,MIN(3-$D11+1,5))) -> 9000000 | I11: =IF(4<$D11,0,$E11*Assumptions!$C$4*INDEX(Assumptions!$C$8:$C$12,MIN(4-$D11+1,5))) -> 27000000 | J11: =IF(5<$D11,0,$E11*Assumptions!$C$4*INDEX(Assumptions!$C$8:$C$12,MIN(5-$D11+1,5))) -> 45000000
A12: 11 | B12: Cotton (feeds Pipeline 22) | C12: A. Agriculture | D12: 4 | E12: 15000000 | F12: =IF(1<$D12,0,$E12*Assumptions!$C$4*INDEX(Assumptions!$C$8:$C$12,MIN(1-$D12+1,5))) -> 0 | G12: =IF(2<$D12,0,$E12*Assumptions!$C$4*INDEX(Assumptions!$C$8:$C$12,MIN(2-$D12+1,5))) -> 0 | H12: =IF(3<$D12,0,$E12*Assumptions!$C$4*INDEX(Assumptions!$C$8:$C$12,MIN(3-$D12+1,5))) -> 0 | I12: =IF(4<$D12,0,$E12*Assumptions!$C$4*INDEX(Assumptions!$C$8:$C$12,MIN(4-$D12+1,5))) -> 3375000 | J12: =IF(5<$D12,0,$E12*Assumptions!$C$4*INDEX(Assumptions!$C$8:$C$12,MIN(5-$D12+1,5))) -> 10125000
A13: 12 | B13: Fisheries & blue economy | C13: A. Agriculture | D13: 3 | E13: 50000000 | F13: =IF(1<$D13,0,$E13*Assumptions!$C$4*INDEX(Assumptions!$C$8:$C$12,MIN(1-$D13+1,5))) -> 0 | G13: =IF(2<$D13,0,$E13*Assumptions!$C$4*INDEX(Assumptions!$C$8:$C$12,MIN(2-$D13+1,5))) -> 0 | H13: =IF(3<$D13,0,$E13*Assumptions!$C$4*INDEX(Assumptions!$C$8:$C$12,MIN(3-$D13+1,5))) -> 11250000 | I13: =IF(4<$D13,0,$E13*Assumptions!$C$4*INDEX(Assumptions!$C$8:$C$12,MIN(4-$D13+1,5))) -> 33750000 | J13: =IF(5<$D13,0,$E13*Assumptions!$C$4*INDEX(Assumptions!$C$8:$C$12,MIN(5-$D13+1,5))) -> 56250000
... A88: 87 | B88: Bulk trade brokerage | C88: M. Flagship & Investment | D88: 5 | E88: 60000000 | F88: =IF(1<$D88,0,$E88*Assumptions!$C$4*INDEX(Assumptions!$C$8:$C$12,MIN(1-$D88+1,5))) -> 0 | G88: =IF(2<$D88,0,$E88*Assumptions!$C$4*INDEX(Assumptions!$C$8:$C$12,MIN(2-$D88+1,5))) -> 0 | H88: =IF(3<$D88,0,$E88*Assumptions!$C$4*INDEX(Assumptions!$C$8:$C$12,MIN(3-$D88+1,5))) -> 0 | I88: =IF(4<$D88,0,$E88*Assumptions!$C$4*INDEX(Assumptions!$C$8:$C$12,MIN(4-$D88+1,5))) -> 0 | J88: =IF(5<$D88,0,$E88*Assumptions!$C$4*INDEX(Assumptions!$C$8:$C$12,MIN(5-$D88+1,5))) -> 13500000
B90: TOTAL — all 87 pipelines (KSh/yr) | F90: =SUM(F2:F88) -> 240750000 | G90: =SUM(G2:G88) -> 981000000 | H90: =SUM(H2:H88) -> 2203875000 | I90: =SUM(I2:I88) -> 3612300000 | J90: =SUM(J2:J88) -> 4780275000

Sheet Category Summary
A1: Category | B1: Year 1 (KSh) | C1: Year 2 (KSh) | D1: Year 3 (KSh) | E1: Year 4 (KSh) | F1: Year 5 (KSh) | G1: 5-Yr CAGR
A2: A. Agriculture | B2: =SUMIFS('Pipeline Model'!F$2:F$88,'Pipeline Model'!$C$2:$C$88,$A2) -> 0 | C2: =SUMIFS('Pipeline Model'!G$2:G$88,'Pipeline Model'!$C$2:$C$88,$A2) -> 121500000 | D2: =SUMIFS('Pipeline Model'!H$2:H$88,'Pipeline Model'!$C$2:$C$88,$A2) -> 427500000 | E2: =SUMIFS('Pipeline Model'!I$2:I$88,'Pipeline Model'!$C$2:$C$88,$A2) -> 832500000 | F2: =SUMIFS('Pipeline Model'!J$2:J$88,'Pipeline Model'!$C$2:$C$88,$A2) -> 1192500000 | G2: =IFERROR((F2/B2)^(1/4)-1,"n/m") -> n/m
A3: B. Minerals | B3: =SUMIFS('Pipeline Model'!F$2:F$88,'Pipeline Model'!$C$2:$C$88,$A3) -> 0 | C3: =SUMIFS('Pipeline Model'!G$2:G$88,'Pipeline Model'!$C$2:$C$88,$A3) -> 0 | D3: =SUMIFS('Pipeline Model'!H$2:H$88,'Pipeline Model'!$C$2:$C$88,$A3) -> 61875000 | E3: =SUMIFS('Pipeline Model'!I$2:I$88,'Pipeline Model'!$C$2:$C$88,$A3) -> 187425000 | F3: =SUMIFS('Pipeline Model'!J$2:J$88,'Pipeline Model'!$C$2:$C$88,$A3) -> 314775000 | G3: =IFERROR((F3/B3)^(1/4)-1,"n/m") -> n/m
A4: C. Industrial & SEZ | B4: =SUMIFS('Pipeline Model'!F$2:F$88,'Pipeline Model'!$C$2:$C$88,$A4) -> 0 | C4: =SUMIFS('Pipeline Model'!G$2:G$88,'Pipeline Model'!$C$2:$C$88,$A4) -> 5625000 | D4: =SUMIFS('Pipeline Model'!H$2:H$88,'Pipeline Model'!$C$2:$C$88,$A4) -> 38250000 | E4: =SUMIFS('Pipeline Model'!I$2:I$88,'Pipeline Model'!$C$2:$C$88,$A4) -> 96750000 | F4: =SUMIFS('Pipeline Model'!J$2:J$88,'Pipeline Model'!$C$2:$C$88,$A4) -> 156000000 | G4: =IFERROR((F4/B4)^(1/4)-1,"n/m") -> n/m
A5: D. Energy & Infra | B5: =SUMIFS('Pipeline Model'!F$2:F$88,'Pipeline Model'!$C$2:$C$88,$A5) -> 0 | C5: =SUMIFS('Pipeline Model'!G$2:G$88,'Pipeline Model'!$C$2:$C$88,$A5) -> 0 | D5: =SUMIFS('Pipeline Model'!H$2:H$88,'Pipeline Model'!$C$2:$C$88,$A5) -> 0 | E5: =SUMIFS('Pipeline Model'!I$2:I$88,'Pipeline Model'!$C$2:$C$88,$A5) -> 16875000 | F5: =SUMIFS('Pipeline Model'!J$2:J$88,'Pipeline Model'!$C$2:$C$88,$A5) -> 52875000 | G5: =IFERROR((F5/B5)^(1/4)-1,"n/m") -> n/m
A6: E. Real Estate | B6: =SUMIFS('Pipeline Model'!F$2:F$88,'Pipeline Model'!$C$2:$C$88,$A6) -> 49500000 | C6: =SUMIFS('Pipeline Model'!G$2:G$88,'Pipeline Model'!$C$2:$C$88,$A6) -> 167625000 | D6: =SUMIFS('Pipeline Model'!H$2:H$88,'Pipeline Model'!$C$2:$C$88,$A6) -> 304875000 | E6: =SUMIFS('Pipeline Model'!I$2:I$88,'Pipeline Model'!$C$2:$C$88,$A6) -> 409125000 | F6: =SUMIFS('Pipeline Model'!J$2:J$88,'Pipeline Model'!$C$2:$C$88,$A6) -> 451125000 | G6: =IFERROR((F6/B6)^(1/4)-1,"n/m") -> 0.73749244
A7: F. Tourism | B7: =SUMIFS('Pipeline Model'!F$2:F$88,'Pipeline Model'!$C$2:$C$88,$A7) -> 78750000 | C7: =SUMIFS('Pipeline Model'!G$2:G$88,'Pipeline Model'!$C$2:$C$88,$A7) -> 258750000 | D7: =SUMIFS('Pipeline Model'!H$2:H$88,'Pipeline Model'!$C$2:$C$88,$A7) -> 478125000 | E7: =SUMIFS('Pipeline Model'!I$2:I$88,'Pipeline Model'!$C$2:$C$88,$A7) -> 661875000 | F7: =SUMIFS('Pipeline Model'!J$2:J$88,'Pipeline Model'!$C$2:$C$88,$A7) -> 751875000 | G7: =IFERROR((F7/B7)^(1/4)-1,"n/m") -> 0.75781745
A8: G. Commerce & Discovery | B8: =SUMIFS('Pipeline Model'!F$2:F$88,'Pipeline Model'!$C$2:$C$88,$A8) -> 109125000 | C8: =SUMIFS('Pipeline Model'!G$2:G$88,'Pipeline Model'!$C$2:$C$88,$A8) -> 327375000 | D8: =SUMIFS('Pipeline Model'!H$2:H$88,'Pipeline Model'!$C$2:$C$88,$A8) -> 558000000 | E8: =SUMIFS('Pipeline Model'!I$2:I$88,'Pipeline Model'!$C$2:$C$88,$A8) -> 728250000 | F8: =SUMIFS('Pipeline Model'!J$2:J$88,'Pipeline Model'!$C$2:$C$88,$A8) -> 789375000 | G8: =IFERROR((F8/B8)^(1/4)-1,"n/m") -> 0.63998463
A9: H. Logistics | B9: =SUMIFS('Pipeline Model'!F$2:F$88,'Pipeline Model'!$C$2:$C$88,$A9) -> 0 | C9: =SUMIFS('Pipeline Model'!G$2:G$88,'Pipeline Model'!$C$2:$C$88,$A9) -> 0 | D9: =SUMIFS('Pipeline Model'!H$2:H$88,'Pipeline Model'!$C$2:$C$88,$A9) -> 32625000 | E9: =SUMIFS('Pipeline Model'!I$2:I$88,'Pipeline Model'!$C$2:$C$88,$A9) -> 97875000 | F9: =SUMIFS('Pipeline Model'!J$2:J$88,'Pipeline Model'!$C$2:$C$88,$A9) -> 163125000 | G9: =IFERROR((F9/B9)^(1/4)-1,"n/m") -> n/m
A10: I. Financial Services | B10: =SUMIFS('Pipeline Model'!F$2:F$88,'Pipeline Model'!$C$2:$C$88,$A10) -> 0 | C10: =SUMIFS('Pipeline Model'!G$2:G$88,'Pipeline Model'!$C$2:$C$88,$A10) -> 11250000 | D10: =SUMIFS('Pipeline Model'!H$2:H$88,'Pipeline Model'!$C$2:$C$88,$A10) -> 33750000 | E10: =SUMIFS('Pipeline Model'!I$2:I$88,'Pipeline Model'!$C$2:$C$88,$A10) -> 83250000 | F10: =SUMIFS('Pipeline Model'!J$2:J$88,'Pipeline Model'!$C$2:$C$88,$A10) -> 165750000 | G10: =IFERROR((F10/B10)^(1/4)-1,"n/m") -> n/m
A11: J. Government | B11: =SUMIFS('Pipeline Model'!F$2:F$88,'Pipeline Model'!$C$2:$C$88,$A11) -> 3375000 | C11: =SUMIFS('Pipeline Model'!G$2:G$88,'Pipeline Model'!$C$2:$C$88,$A11) -> 25875000 | D11: =SUMIFS('Pipeline Model'!H$2:H$88,'Pipeline Model'!$C$2:$C$88,$A11) -> 64125000 | E11: =SUMIFS('Pipeline Model'!I$2:I$88,'Pipeline Model'!$C$2:$C$88,$A11) -> 100125000 | F11: =SUMIFS('Pipeline Model'!J$2:J$88,'Pipeline Model'!$C$2:$C$88,$A11) -> 122250000 | G11: =IFERROR((F11/B11)^(1/4)-1,"n/m") -> 1.4532611
A12: K. Additional Sectors | B12: =SUMIFS('Pipeline Model'!F$2:F$88,'Pipeline Model'!$C$2:$C$88,$A12) -> 0 | C12: =SUMIFS('Pipeline Model'!G$2:G$88,'Pipeline Model'!$C$2:$C$88,$A12) -> 0 | D12: =SUMIFS('Pipeline Model'!H$2:H$88,'Pipeline Model'!$C$2:$C$88,$A12) -> 15750000 | E12: =SUMIFS('Pipeline Model'!I$2:I$88,'Pipeline Model'!$C$2:$C$88,$A12) -> 63000000 | F12: =SUMIFS('Pipeline Model'!J$2:J$88,'Pipeline Model'!$C$2:$C$88,$A12) -> 126000000 | G12: =IFERROR((F12/B12)^(1/4)-1,"n/m") -> n/m
A13: L. RE Rental Expansion | B13: =SUMIFS('Pipeline Model'!F$2:F$88,'Pipeline Model'!$C$2:$C$88,$A13) -> 0 | C13: =SUMIFS('Pipeline Model'!G$2:G$88,'Pipeline Model'!$C$2:$C$88,$A13) -> 63000000 | D13: =SUMIFS('Pipeline Model'!H$2:H$88,'Pipeline Model'!$C$2:$C$88,$A13) -> 189000000 | E13: =SUMIFS('Pipeline Model'!I$2:I$88,'Pipeline Model'!$C$2:$C$88,$A13) -> 315000000 | F13: =SUMIFS('Pipeline Model'!J$2:J$88,'Pipeline Model'!$C$2:$C$88,$A13) -> 399000000 | G13: =IFERROR((F13/B13)^(1/4)-1,"n/m") -> n/m
A14: M. Flagship & Investment | B14: =SUMIFS('Pipeline Model'!F$2:F$88,'Pipeline Model'!$C$2:$C$88,$A14) -> 0 | C14: =SUMIFS('Pipeline Model'!G$2:G$88,'Pipeline Model'!$C$2:$C$88,$A14) -> 0 | D14: =SUMIFS('Pipeline Model'!H$2:H$88,'Pipeline Model'!$C$2:$C$88,$A14) -> 0 | E14: =SUMIFS('Pipeline Model'!I$2:I$88,'Pipeline Model'!$C$2:$C$88,$A14) -> 20250000 | F14: =SUMIFS('Pipeline Model'!J$2:J$88,'Pipeline Model'!$C$2:$C$88,$A14) -> 95625000 | G14: =IFERROR((F14/B14)^(1/4)-1,"n/m") -> n/m
A15: TOTAL | B15: =SUM(B2:B14) -> 240750000 | C15: =SUM(C2:C14) -> 981000000 | D15: =SUM(D2:D14) -> 2203875000 | E15: =SUM(E2:E14) -> 3612300000 | F15: =SUM(F2:F14) -> 4780275000

Sheet Advertising & Media Cost
A1: Advertising & Media Cost by Category — Screentime vs. Airtime
A2: Marketing cost = category revenue (Category Summary) x Assumptions!marketing-to-revenue ratio for that year, split by the channel-mix % on the Assumptions sheet.
A4: Category | B4: Screentime % | C4: Airtime % | D4: Y1 Marketing | E4: Y1 Screentime | F4: Y1 Airtime | G4: Y2 Marketing | H4: Y2 Screentime | I4: Y2 Airtime | J4: Y3 Marketing | K4: Y3 Screentime | L4: Y3 Airtime | M4: Y4 Marketing | N4: Y4 Screentime | O4: Y4 Airtime | P4: Y5 Marketing | Q4: Y5 Screentime | R4: Y5 Airtime
A5: A. Agriculture | B5: =Assumptions!$C$24 -> 0.3 | C5: =Assumptions!$D$24 -> 0.7 | D5: ='Category Summary'!B2*INDEX(Assumptions!$C$16:$C$20,1) -> 0 | E5: =D5*$B5 -> 0 | F5: =D5*$C5 -> 0 | G5: ='Category Summary'!C2*INDEX(Assumptions!$C$16:$C$20,2) -> 13365000 | H5: =G5*$B5 -> 4009500 | I5: =G5*$C5 -> 9355500 | J5: ='Category Summary'!D2*INDEX(Assumptions!$C$16:$C$20,3) -> 38475000 | K5: =J5*$B5 -> 11542500 | L5: =J5*$C5 -> 26932500 | M5: ='Category Summary'!E2*INDEX(Assumptions!$C$16:$C$20,4) -> 58275000 | N5: =M5*$B5 -> 17482500 | O5: =M5*$C5 -> 40792500 | P5: ='Category Summary'!F2*INDEX(Assumptions!$C$16:$C$20,5) -> 71550000 | Q5: =P5*$B5 -> 21465000 | R5: =P5*$C5 -> 50085000
A6: B. Minerals | B6: =Assumptions!$C$25 -> 0.4 | C6: =Assumptions!$D$25 -> 0.6 | D6: ='Category Summary'!B3*INDEX(Assumptions!$C$16:$C$20,1) -> 0 | E6: =D6*$B6 -> 0 | F6: =D6*$C6 -> 0 | G6: ='Category Summary'!C3*INDEX(Assumptions!$C$16:$C$20,2) -> 0 | H6: =G6*$B6 -> 0 | I6: =G6*$C6 -> 0 | J6: ='Category Summary'!D3*INDEX(Assumptions!$C$16:$C$20,3) -> 5568750 | K6: =J6*$B6 -> 2227500 | L6: =J6*$C6 -> 3341250 | M6: ='Category Summary'!E3*INDEX(Assumptions!$C$16:$C$20,4) -> 13119750 | N6: =M6*$B6 -> 5247900 | O6: =M6*$C6 -> 7871850 | P6: ='Category Summary'!F3*INDEX(Assumptions!$C$16:$C$20,5) -> 18886500 | Q6: =P6*$B6 -> 7554600 | R6: =P6*$C6 -> 11331900
A7: C. Industrial & SEZ | B7: =Assumptions!$C$26 -> 0.6 | C7: =Assumptions!$D$26 -> 0.4 | D7: ='Category Summary'!B4*INDEX(Assumptions!$C$16:$C$20,1) -> 0 | E7: =D7*$B7 -> 0 | F7: =D7*$C7 -> 0 | G7: ='Category Summary'!C4*INDEX(Assumptions!$C$16:$C$20,2) -> 618750 | H7: =G7*$B7 -> 371250 | I7: =G7*$C7 -> 247500 | J7: ='Category Summary'!D4*INDEX(Assumptions!$C$16:$C$20,3) -> 3442500 | K7: =J7*$B7 -> 2065500 | L7: =J7*$C7 -> 1377000 | M7: ='Category Summary'!E4*INDEX(Assumptions!$C$16:$C$20,4) -> 6772500 | N7: =M7*$B7 -> 4063500 | O7: =M7*$C7 -> 2709000 | P7: ='Category Summary'!F4*INDEX(Assumptions!$C$16:$C$20,5) -> 9360000 | Q7: =P7*$B7 -> 5616000 | R7: =P7*$C7 -> 3744000
A8: D. Energy & Infra | B8: =Assumptions!$C$27 -> 0.55 | C8: =Assumptions!$D$27 -> 0.45 | D8: ='Category Summary'!B5*INDEX(Assumptions!$C$16:$C$20,1) -> 0 | E8: =D8*$B8 -> 0 | F8: =D8*$C8 -> 0 | G8: ='Category Summary'!C5*INDEX(Assumptions!$C$16:$C$20,2) -> 0 | H8: =G8*$B8 -> 0 | I8: =G8*$C8 -> 0 | J8: ='Category Summary'!D5*INDEX(Assumptions!$C$16:$C$20,3) -> 0 | K8: =J8*$B8 -> 0 | L8: =J8*$C8 -> 0 | M8: ='Category Summary'!E5*INDEX(Assumptions!$C$16:$C$20,4) -> 1181250 | N8: =M8*$B8 -> 649687.5 | O8: =M8*$C8 -> 531562.5 | P8: ='Category Summary'!F5*INDEX(Assumptions!$C$16:$C$20,5) -> 3172500 | Q8: =P8*$B8 -> 1744875 | R8: =P8*$C8 -> 1427625
A9: E. Real Estate | B9: =Assumptions!$C$28 -> 0.7 | C9: =Assumptions!$D$28 -> 0.3 | D9: ='Category Summary'!B6*INDEX(Assumptions!$C$16:$C$20,1) -> 6930000 | E9: =D9*$B9 -> 4851000 | F9: =D9*$C9 -> 2079000 | G9: ='Category Summary'!C6*INDEX(Assumptions!$C$16:$C$20,2) -> 18438750 | H9: =G9*$B9 -> 12907125 | I9: =G9*$C9 -> 5531625 | J9: ='Category Summary'!D6*INDEX(Assumptions!$C$16:$C$20,3) -> 27438750 | K9: =J9*$B9 -> 19207125 | L9: =J9*$C9 -> 8231625 | M9: ='Category Summary'!E6*INDEX(Assumptions!$C$16:$C$20,4) -> 28638750 | N9: =M9*$B9 -> 20047125 | O9: =M9*$C9 -> 8591625 | P9: ='Category Summary'!F6*INDEX(Assumptions!$C$16:$C$20,5) -> 27067500 | Q9: =P9*$B9 -> 18947250 | R9: =P9*$C9 -> 8120250
A10: F. Tourism | B10: =Assumptions!$C$29 -> 0.75 | C10: =Assumptions!$D$29 -> 0.25 | D10: ='Category Summary'!B7*INDEX(Assumptions!$C$16:$C$20,1) -> 11025000 | E10: =D10*$B10 -> 8268750 | F10: =D10*$C10 -> 2756250 | G10: ='Category Summary'!C7*INDEX(Assumptions!$C$16:$C$20,2) -> 28462500 | H10: =G10*$B10 -> 21346875 | I10: =G10*$C10 -> 7115625 | J10: ='Category Summary'!D7*INDEX(Assumptions!$C$16:$C$20,3) -> 43031250 | K10: =J10*$B10 -> 32273438 | L10: =J10*$C10 -> 10757812 | M10: ='Category Summary'!E7*INDEX(Assumptions!$C$16:$C$20,4) -> 46331250 | N10: =M10*$B10 -> 34748438 | O10: =M10*$C10 -> 11582812 | P10: ='Category Summary'!F7*INDEX(Assumptions!$C$16:$C$20,5) -> 45112500 | Q10: =P10*$B10 -> 33834375 | R10: =P10*$C10 -> 11278125
A11: G. Commerce & Discovery | B11: =Assumptions!$C$30 -> 0.65 | C11: =Assumptions!$D$30 -> 0.35 | D11: ='Category Summary'!B8*INDEX(Assumptions!$C$16:$C$20,1) -> 15277500 | E11: =D11*$B11 -> 9930375 | F11: =D11*$C11 -> 5347125 | G11: ='Category Summary'!C8*INDEX(Assumptions!$C$16:$C$20,2) -> 36011250 | H11: =G11*$B11 -> 23407312 | I11: =G11*$C11 -> 12603938 | J11: ='Category Summary'!D8*INDEX(Assumptions!$C$16:$C$20,3) -> 50220000 | K11: =J11*$B11 -> 32643000 | L11: =J11*$C11 -> 17577000 | M11: ='Category Summary'!E8*INDEX(Assumptions!$C$16:$C$20,4) -> 50977500 | N11: =M11*$B11 -> 33135375 | O11: =M11*$C11 -> 17842125 | P11: ='Category Summary'!F8*INDEX(Assumptions!$C$16:$C$20,5) -> 47362500 | Q11: =P11*$B11 -> 30785625 | R11: =P11*$C11 -> 16576875
A12: H. Logistics | B12: =Assumptions!$C$31 -> 0.5 | C12: =Assumptions!$D$31 -> 0.5 | D12: ='Category Summary'!B9*INDEX(Assumptions!$C$16:$C$20,1) -> 0 | E12: =D12*$B12 -> 0 | F12: =D12*$C12 -> 0 | G12: ='Category Summary'!C9*INDEX(Assumptions!$C$16:$C$20,2) -> 0 | H12: =G12*$B12 -> 0 | I12: =G12*$C12 -> 0 | J12: ='Category Summary'!D9*INDEX(Assumptions!$C$16:$C$20,3) -> 2936250 | K12: =J12*$B12 -> 1468125 | L12: =J12*$C12 -> 1468125 | M12: ='Category Summary'!E9*INDEX(Assumptions!$C$16:$C$20,4) -> 6851250 | N12: =M12*$B12 -> 3425625 | O12: =M12*$C12 -> 3425625 | P12: ='Category Summary'!F9*INDEX(Assumptions!$C$16:$C$20,5) -> 9787500 | Q12: =P12*$B12 -> 4893750 | R12: =P12*$C12 -> 4893750
A13: I. Financial Services | B13: =Assumptions!$C$32 -> 0.6 | C13: =Assumptions!$D$32 -> 0.4 | D13: ='Category Summary'!B10*INDEX(Assumptions!$C$16:$C$20,1) -> 0 | E13: =D13*$B13 -> 0 | F13: =D13*$C13 -> 0 | G13: ='Category Summary'!C10*INDEX(Assumptions!$C$16:$C$20,2) -> 1237500 | H13: =G13*$B13 -> 742500 | I13: =G13*$C13 -> 495000 | J13: ='Category Summary'!D10*INDEX(Assumptions!$C$16:$C$20,3) -> 3037500 | K13: =J13*$B13 -> 1822500 | L13: =J13*$C13 -> 1215000 | M13: ='Category Summary'!E10*INDEX(Assumptions!$C$16:$C$20,4) -> 5827500 | N13: =M13*$B13 -> 3496500 | O13: =M13*$C13 -> 2331000 | P13: ='Category Summary'!F10*INDEX(Assumptions!$C$16:$C$20,5) -> 9945000 | Q13: =P13*$B13 -> 5967000 | R13: =P13*$C13 -> 3978000
A14: J. Government | B14: =Assumptions!$C$33 -> 0.35 | C14: =Assumptions!$D$33 -> 0.65 | D14: ='Category Summary'!B11*INDEX(Assumptions!$C$16:$C$20,1) -> 472500 | E14: =D14*$B14 -> 165375 | F14: =D14*$C14 -> 307125 | G14: ='Category Summary'!C11*INDEX(Assumptions!$C$16:$C$20,2) -> 2846250 | H14: =G14*$B14 -> 996187.5 | I14: =G14*$C14 -> 1850062.5 | J14: ='Category Summary'!D11*INDEX(Assumptions!$C$16:$C$20,3) -> 5771250 | K14: =J14*$B14 -> 2019937.5 | L14: =J14*$C14 -> 3751312.5 | M14: ='Category Summary'!E11*INDEX(Assumptions!$C$16:$C$20,4) -> 7008750 | N14: =M14*$B14 -> 2453062.5 | O14: =M14*$C14 -> 4555687.5 | P14: ='Category Summary'!F11*INDEX(Assumptions!$C$16:$C$20,5) -> 7335000 | Q14: =P14*$B14 -> 2567250 | R14: =P14*$C14 -> 4767750
A15: K. Additional Sectors | B15: =Assumptions!$C$34 -> 0.5 | C15: =Assumptions!$D$34 -> 0.5 | D15: ='Category Summary'!B12*INDEX(Assumptions!$C$16:$C$20,1) -> 0 | E15: =D15*$B15 -> 0 | F15: =D15*$C15 -> 0 | G15: ='Category Summary'!C12*INDEX(Assumptions!$C$16:$C$20,2) -> 0 | H15: =G15*$B15 -> 0 | I15: =G15*$C15 -> 0 | J15: ='Category Summary'!D12*INDEX(Assumptions!$C$16:$C$20,3) -> 1417500 | K15: =J15*$B15 -> 708750 | L15: =J15*$C15 -> 708750 | M15: ='Category Summary'!E12*INDEX(Assumptions!$C$16:$C$20,4) -> 4410000 | N15: =M15*$B15 -> 2205000 | O15: =M15*$C15 -> 2205000 | P15: ='Category Summary'!F12*INDEX(Assumptions!$C$16:$C$20,5) -> 7560000 | Q15: =P15*$B15 -> 3780000 | R15: =P15*$C15 -> 3780000
A16: L. RE Rental Expansion | B16: =Assumptions!$C$35 -> 0.7 | C16: =Assumptions!$D$35 -> 0.3 | D16: ='Category Summary'!B13*INDEX(Assumptions!$C$16:$C$20,1) -> 0 | E16: =D16*$B16 -> 0 | F16: =D16*$C16 -> 0 | G16: ='Category Summary'!C13*INDEX(Assumptions!$C$16:$C$20,2) -> 6930000 | H16: =G16*$B16 -> 4851000 | I16: =G16*$C16 -> 2079000 | J16: ='Category Summary'!D13*INDEX(Assumptions!$C$16:$C$20,3) -> 17010000 | K16: =J16*$B16 -> 11907000 | L16: =J16*$C16 -> 5103000 | M16: ='Category Summary'!E13*INDEX(Assumptions!$C$16:$C$20,4) -> 22050000 | N16: =M16*$B16 -> 15435000 | O16: =M16*$C16 -> 6615000 | P16: ='Category Summary'!F13*INDEX(Assumptions!$C$16:$C$20,5) -> 23940000 | Q16: =P16*$B16 -> 16758000 | R16: =P16*$C16 -> 7182000
A17: M. Flagship & Investment | B17: =Assumptions!$C$36 -> 0.65 | C17: =Assumptions!$D$36 -> 0.35 | D17: ='Category Summary'!B14*INDEX(Assumptions!$C$16:$C$20,1) -> 0 | E17: =D17*$B17 -> 0 | F17: =D17*$C17 -> 0 | G17: ='Category Summary'!C14*INDEX(Assumptions!$C$16:$C$20,2) -> 0 | H17: =G17*$B17 -> 0 | I17: =G17*$C17 -> 0 | J17: ='Category Summary'!D14*INDEX(Assumptions!$C$16:$C$20,3) -> 0 | K17: =J17*$B17 -> 0 | L17: =J17*$C17 -> 0 | M17: ='Category Summary'!E14*INDEX(Assumptions!$C$16:$C$20,4) -> 1417500 | N17: =M17*$B17 -> 921375 | O17: =M17*$C17 -> 496125 | P17: ='Category Summary'!F14*INDEX(Assumptions!$C$16:$C$20,5) -> 5737500 | Q17: =P17*$B17 -> 3729375 | R17: =P17*$C17 -> 2008125
A18: TOTAL | D18: =SUM(D5:D17) -> 33705000 | E18: =SUM(E5:E17) -> 23215500 | F18: =SUM(F5:F17) -> 10489500 | G18: =SUM(G5:G17) -> 107910000 | H18: =SUM(H5:H17) -> 68631750 | I18: =SUM(I5:I17) -> 39278250 | J18: =SUM(J5:J17) -> 198348750 | K18: =SUM(K5:K17) -> 117885375 | ... R18: =SUM(R5:R17) -> 129173400
